/home2/johannae/anaconda3/lib/python3.9/site-packages/torch/distributed/launch.py:178: FutureWarning: The module torch.distributed.launch is deprecated
and will be removed in future. Use torchrun.
Note that --use_env is set by default in torchrun.
If your script expects `--local_rank` argument to be set, please
change it to read from `os.environ['LOCAL_RANK']` instead. See 
https://pytorch.org/docs/stable/distributed.html#launch-utility for 
further instructions

  warnings.warn(
/home2/johannae/anaconda3/bin/python: can't open file '/home2/johannae/semi-lines/UniMatch/scripts/supervised.py': [Errno 2] No such file or directory
ERROR:torch.distributed.elastic.multiprocessing.api:failed (exitcode: 2) local_rank: 0 (pid: 5033) of binary: /home2/johannae/anaconda3/bin/python
Traceback (most recent call last):
  File "/home2/johannae/anaconda3/lib/python3.9/runpy.py", line 197, in _run_module_as_main
    return _run_code(code, main_globals, None,
  File "/home2/johannae/anaconda3/lib/python3.9/runpy.py", line 87, in _run_code
    exec(code, run_globals)
  File "/home2/johannae/anaconda3/lib/python3.9/site-packages/torch/distributed/launch.py", line 193, in <module>
    main()
  File "/home2/johannae/anaconda3/lib/python3.9/site-packages/torch/distributed/launch.py", line 189, in main
    launch(args)
  File "/home2/johannae/anaconda3/lib/python3.9/site-packages/torch/distributed/launch.py", line 174, in launch
    run(args)
  File "/home2/johannae/anaconda3/lib/python3.9/site-packages/torch/distributed/run.py", line 752, in run
    elastic_launch(
  File "/home2/johannae/anaconda3/lib/python3.9/site-packages/torch/distributed/launcher/api.py", line 131, in __call__
    return launch_agent(self._config, self._entrypoint, list(args))
  File "/home2/johannae/anaconda3/lib/python3.9/site-packages/torch/distributed/launcher/api.py", line 245, in launch_agent
    raise ChildFailedError(
torch.distributed.elastic.multiprocessing.errors.ChildFailedError: 
============================================================
supervised.py FAILED
------------------------------------------------------------
Failures:
  <NO_OTHER_FAILURES>
------------------------------------------------------------
Root Cause (first observed failure):
[0]:
  time      : 2023-08-18_15:05:23
  host      : weibull
  rank      : 0 (local_rank: 0)
  exitcode  : 2 (pid: 5033)
  error_file: <N/A>
  traceback : To enable traceback see: https://pytorch.org/docs/stable/elastic/errors.html
============================================================
